Workbook

Sheet Model
A1: Agentic Coach Cost + Gross Profit Model
A2: Edit yellow cells only. All blue/white cells are calculated.
A4: Operational Inputs
A5: Users | B5: 500 | C5: Example cohort size
A6: Sessions per user | B6: 30 | C6: Per pricing period
A7: Session duration (minutes) | B7: 15 | C7: Current design cap
A8: Chat turns per session | B8: 18 | C8: Average
A9: Input tokens per turn | B9: 1400 | C9: LLM prompt + history
A10: Output tokens per turn | B10: 180 | C10: Assistant response
A11: TTS minutes per session | B11: 6 | C11: Assistant spoken minutes
A12: STT API minutes per session | B12: 0.5 | C12: Fallback/upload STT only
A13: API Pricing Inputs (USD)
A14: LLM input price ($ per 1M tokens) | B14: 0.15 | C14: gpt-4o-mini reference
A15: LLM output price ($ per 1M tokens) | B15: 0.6 | C15: gpt-4o-mini reference
A16: TTS price ($ per minute) | B16: 0.015 | C16: gpt-4o-mini-tts assumption
A17: STT price ($ per minute) | B17: 0.006 | C17: whisper/transcribe benchmark
A18: Hosting + Fixed Monthly Costs (USD)
A19: Vercel fixed monthly cost | B19: 20 | C19: Pro plan baseline
A20: MongoDB fixed monthly cost | B20: 30 | C20: Atlas flex baseline
A21: Other fixed monthly costs | B21: 0 | C21: Monitoring, logging, etc.
A22: Commercial Inputs (USD)
A23: Price per user (monthly) | B23: 19 | C23: Retail/subscription
A24: Price per user (annual) | B24: 180 | C24: Optional annual package
A25: Derived Volumes
A26: Total sessions | B26: =B5*B6 | C26: Users x sessions per user
A27: Total coaching minutes | B27: =B26*B7
A28: Total chat turns | B28: =B26*B8
A29: Total input tokens | B29: =B28*B9
A30: Total output tokens | B30: =B28*B10
A31: Total TTS minutes | B31: =B26*B11
A32: Total STT API minutes | B32: =B26*B12
A33: Cost Breakdown (USD)
A34: LLM input cost | B34: =B29/1000000*B14
A35: LLM output cost | B35: =B30/1000000*B15
A36: TTS cost | B36: =B31*B16
A37: STT cost | B37: =B32*B17
A38: Variable AI cost total | B38: =SUM(B34:B37)
A39: Fixed hosting cost total | B39: =SUM(B19:B21)
A40: Total run cost | B40: =B38+B39
A41: Variable cost per user | B41: =IF(B5=0,0,B38/B5) | C41: Use for monthly tracker
...

Sheet Scenarios
A1: Scenario Comparison
A2: Baseline pulls from Model inputs. Edit Optimized assumptions in column C.
A4: Metric | B4: Baseline | C4: Optimized | D4: Notes
A5: Users | B5: =Model!B5 | C5: =Model!B5
A6: Sessions per user | B6: =Model!B6 | C6: =Model!B6
A7: Session minutes | B7: =Model!B7 | C7: =Model!B7
A8: Chat turns/session | B8: =Model!B8 | C8: =Model!B8
A9: Input tokens/turn | B9: =Model!B9 | C9: 1200 | D9: Lower via prompt compaction/caching
A10: Output tokens/turn | B10: =Model!B10 | C10: 150 | D10: Shorter responses
A11: TTS mins/session | B11: =Model!B11 | C11: 4 | D11: Most impactful cost lever
A12: STT mins/session | B12: =Model!B12 | C12: 0.25 | D12: Fallback only
A13: LLM input $/1M | B13: =Model!B14 | C13: =Model!B14
A14: LLM output $/1M | B14: =Model!B15 | C14: =Model!B15
A15: TTS $/min | B15: =Model!B16 | C15: =Model!B16
A16: STT $/min | B16: =Model!B17 | C16: =Model!B17
A18: Computed Costs and Profit
A19: Total sessions | B19: =B5*B6 | C19: =C5*C6
A20: LLM input cost | B20: =B14*B8*B9*B17/1000000 | C20: =C14*C8*C9*C17/1000000
A21: LLM output cost | B21: =B14*B8*B10*B18/1000000 | C21: =C14*C8*C10*C18/1000000
A22: TTS cost | B22: =B14*B11*B19 | C22: =C14*C11*C19
A23: STT cost | B23: =B14*B12*B20 | C23: =C14*C12*C20
A24: Variable AI total | B24: =SUM(B20:B23) | C24: =SUM(C20:C23)
A25: Fixed hosting | B25: =Model!B39 | C25: =Model!B39
A26: Total run cost | B26: =B24+B25 | C26: =C24+C25
A27: Revenue | B27: =B5*Model!B23 | C27: =C5*Model!B23
A28: Gross profit | B28: =B27-B26 | C28: =C27-C26
A29: Gross margin % | B29: =IF(B27=0,0,B28/B27) | C29: =IF(C27=0,0,C28/C27)
A30: Savings vs baseline | C30: =B26-C26 | D30: Positive means optimized is cheaper

Sheet Monthly_Tracker
A1: Monthly Cost + Gross Profit Tracker
A2: Edit Active Users, Sessions/User, and Price/User as needed. Cost/User is linked from Model variable cost.
A4: Month | B4: Active Users | C4: Sessions/User | D4: Price/User | E4: Revenue | F4: Variable Cost/User | G4: Fixed Cost | H4: Total Cost | I4: Gross Profit | J4: Gross Margin %
A5: Jan | B5: =Model!B5 | C5: =Model!B6 | D5: =Model!B23 | E5: =B5*D5 | F5: =Model!B41 | G5: =Model!B39 | H5: =B5*F5+G5 | I5: =E5-H5 | J5: =IF(E5=0,0,I5/E5)
A6: Feb | B6: =Model!B5 | C6: =Model!B6 | D6: =Model!B23 | E6: =B6*D6 | F6: =Model!B41 | G6: =Model!B39 | H6: =B6*F6+G6 | I6: =E6-H6 | J6: =IF(E6=0,0,I6/E6)
A7: Mar | B7: =Model!B5 | C7: =Model!B6 | D7: =Model!B23 | E7: =B7*D7 | F7: =Model!B41 | G7: =Model!B39 | H7: =B7*F7+G7 | I7: =E7-H7 | J7: =IF(E7=0,0,I7/E7)
A8: Apr | B8: =Model!B5 | C8: =Model!B6 | D8: =Model!B23 | E8: =B8*D8 | F8: =Model!B41 | G8: =Model!B39 | H8: =B8*F8+G8 | I8: =E8-H8 | J8: =IF(E8=0,0,I8/E8)
A9: May | B9: =Model!B5 | C9: =Model!B6 | D9: =Model!B23 | E9: =B9*D9 | F9: =Model!B41 | G9: =Model!B39 | H9: =B9*F9+G9 | I9: =E9-H9 | J9: =IF(E9=0,0,I9/E9)
A10: Jun | B10: =Model!B5 | C10: =Model!B6 | D10: =Model!B23 | E10: =B10*D10 | F10: =Model!B41 | G10: =Model!B39 | H10: =B10*F10+G10 | I10: =E10-H10 | J10: =IF(E10=0,0,I10/E10)
A11: Jul | B11: =Model!B5 | C11: =Model!B6 | D11: =Model!B23 | E11: =B11*D11 | F11: =Model!B41 | G11: =Model!B39 | H11: =B11*F11+G11 | I11: =E11-H11 | J11: =IF(E11=0,0,I11/E11)
A12: Aug | B12: =Model!B5 | C12: =Model!B6 | D12: =Model!B23 | E12: =B12*D12 | F12: =Model!B41 | G12: =Model!B39 | H12: =B12*F12+G12 | I12: =E12-H12 | J12: =IF(E12=0,0,I12/E12)
A13: Sep | B13: =Model!B5 | C13: =Model!B6 | D13: =Model!B23 | E13: =B13*D13 | F13: =Model!B41 | G13: =Model!B39 | H13: =B13*F13+G13 | I13: =E13-H13 | J13: =IF(E13=0,0,I13/E13)
A14: Oct | B14: =Model!B5 | C14: =Model!B6 | D14: =Model!B23 | E14: =B14*D14 | F14: =Model!B41 | G14: =Model!B39 | H14: =B14*F14+G14 | I14: =E14-H14 | J14: =IF(E14=0,0,I14/E14)
A15: Nov | B15: =Model!B5 | C15: =Model!B6 | D15: =Model!B23 | E15: =B15*D15 | F15: =Model!B41 | G15: =Model!B39 | H15: =B15*F15+G15 | I15: =E15-H15 | J15: =IF(E15=0,0,I15/E15)
A16: Dec | B16: =Model!B5 | C16: =Model!B6 | D16: =Model!B23 | E16: =B16*D16 | F16: =Model!B41 | G16: =Model!B39 | H16: =B16*F16+G16 | I16: =E16-H16 | J16: =IF(E16=0,0,I16/E16)
A17: Total | E17: =SUM(E5:E16) | H17: =SUM(H5:H16) | I17: =SUM(I5:I16) | J17: =IF(E17=0,0,I17/E17)

Sheet Quote_Summary
A1: Client Quote Summary
A3: Volume
A4: Users | B4: =Model!B5
A5: Sessions per user | B5: =Model!B6
A6: Session minutes | B6: =Model!B7
A7: Total sessions | B7: =Model!B26
A9: Costs
A10: Total run cost | B10: =Model!B40
A11: Cost per user | B11: =Model!B42
A12: Cost per session | B12: =Model!B43
A15: Commercials
A16: Price per user (monthly) | B16: =Model!B23
A17: Total revenue | B17: =Model!B45
A18: Gross profit | B18: =Model!B46
A19: Gross margin % | B19: =Model!B47

Sheet Simple_Pricing
A1: Simple Pricing (Monthly)
A2: For up to 30 sessions/user, 15 mins/session. Edit yellow cells only.
A4: Assumptions
A5: Sessions per user (monthly) | B5: =Model!B6 | C5: Default from Model
A6: Session duration (minutes) | B6: =Model!B7 | C6: Default from Model
A7: Run cost per user (monthly) | B7: =Model!B42 | C7: Includes AI + allocated hosting
A8: Suggested price per individual user | B8: 19 | C8: You can change this
A9: Suggested price per user (1000-user client) | B9: 14 | C9: Volume pricing
A10: Enterprise user count | B10: 1000 | C10: Client size
A13: Single User (1 user)
A14: Cost | B14: =B7
A15: Price | B15: =B8
A16: Gross profit | B16: =B15-B14
A17: Gross margin % | B17: =IF(B15=0,0,B16/B15)
A20: 1000 Users (or value in Enterprise user count)
A21: Total cost | B21: =B7*B10
A22: Total price | B22: =B9*B10
A23: Gross profit | B23: =B22-B21
A24: Gross margin % | B24: =IF(B22=0,0,B23/B22)
A25: Price per user | B25: =B9
A26: Profit per user | B26: =IF(B10=0,0,B23/B10)
A29: Quick Recommendation
A30: Recommended individual price | B30: =B8
A31: Recommended 1000-user client price per user | B31: =B9
A32: Recommended total monthly quote for 1000 users | B32: =B22
